<mujoco model="balance_rover">
  <compiler inertiafromgeom="true"/>

  <default>
    <joint   armature="0" damping="1"/>
    <geom    friction="1 0.1 0.1"/>
    <motor   ctrlrange="-5 5"/>
  </default>

  <option gravity="0 0 -9.81" integrator="RK4" timestep="0.0005"/>

  <worldbody>
    <!-- floor plane -->
    <geom type="plane" pos="0 0 0" size="5 5 0.1"
          contype="1" conaffinity="1"
          friction="1 0.1 0.1"
          rgba="0.8 0.8 0.8 1"/>

    <body name="base" pos="0 0 0.02">
      <joint name="slide" type="slide" axis="1 0 0" range="-5 5"/>
      <inertial pos="0 0 0" mass="1.0" diaginertia="0.001 0.001 0.001"/>

      <!-- Left wheel -->
      <body name="wheel_L" pos="0  0.05 0.02">
        <joint name="L_spin" type="hinge" axis="0 1 0" limited="false"/>
        <inertial pos="0 0 0" mass="0.3" diaginertia="0.0001 0.0001 0.0001"/>
        <geom  type="cylinder"
               size="0.06 0.005"
               quat="0.7071 0.7071 0 0"
               contype="1" conaffinity="1"
               friction="1 0.1 0.1"
               rgba="0.2 0.2 0.2 1"/>
      </body>

      <!-- Right wheel -->
      <body name="wheel_R" pos="0 -0.05 0.02">
        <joint name="R_spin" type="hinge" axis="0 1 0" limited="false"/>
        <inertial pos="0 0 0" mass="0.3" diaginertia="0.0001 0.0001 0.0001"/>
        <geom  type="cylinder"
               size="0.06 0.005"
               quat="0.7071 0.7071 0 0"
               contype="1" conaffinity="1"
               friction="1 0.1 0.1"
               rgba="0.2 0.2 0.2 1"/>
      </body>

      <!-- Pendulum pole -->
      <body name="pole" pos="0 0 0.04">
        <joint name="hinge" type="hinge" axis="0 1 0" damping="0.0" limited="false"/>
        <geom type="capsule"
              fromto="0 0 0  0 0 0.5"
              size="0.02"
              rgba="0.8 0.3 0.3 1"/>
      </body>

    </body> <!-- Missing closing tag for base added here -->
  </worldbody>

  <actuator>
    <!-- Two independent wheel motors -->
    <motor joint="L_spin" name="u_L" ctrlrange="-3 3" gear="100"/>
    <motor joint="R_spin" name="u_R" ctrlrange="-3 3" gear="100"/>
  </actuator>
</mujoco>
